<?xml version="1.0"?>
<!-- Generated using onshape-to-robot -->
<!-- Onshape document_id: 9c20b098af12cbd02fc50d1f / workspace_id: 91f9e8051518d9fb326b8e23 -->
<mujoco model="robot">
  <compiler angle="radian" meshdir="../meshes" autolimits="true"/>
  <default>
    <default class="robot">
      <joint frictionloss="0.1" armature="0.005"/>
      <position kp="50" dampratio="1"/>
      <default class="visual">
        <geom type="mesh" contype="0" conaffinity="0" group="2"/>
      </default>
      <default class="collision">
        <geom group="3"/>
      </default>
    </default>
  </default>
  <worldbody>
    <!-- Link base_link -->
    <body name="base_link" pos="0 0 0" quat="1 0 0 0" childclass="robot">
      <inertial pos="-2.49848e-17 -1.10765e-17 0.0498616" mass="4.06535" fullinertia="0.140289 0.140289 0.220217 3.41547e-24 0 0"/>
      <!-- Part part_1 -->
      <geom type="mesh" class="visual" pos="0 0 0" quat="0.707107 0 0 0.707107" mesh="part_1" material="part_1_material"/>
      <geom type="mesh" class="collision" pos="0 0 0" quat="0.707107 0 0 0.707107" mesh="part_1" material="part_1_material"/>
      <!-- Link part_1 -->
      <body name="part_1" pos="-1.73472e-18 0 0.34925" quat="1.60032e-17 -0.707107 -0.707107 4.30998e-18">
        <!-- Joint from base_link to part_1 -->
        <joint axis="0 0 1" name="yaw" type="hinge"/>
        <inertial pos="0 0 0" mass="1e-09" fullinertia="1e-09 1e-09 1e-09 0 0 0"/>
        <!-- Part part_1_2 -->
        <geom type="mesh" class="visual" pos="-0.0315 -0.0105 0" quat="0 1 0 0" mesh="part_1__2" material="part_1__2_material"/>
        <geom type="mesh" class="collision" pos="-0.0315 -0.0105 0" quat="0 1 0 0" mesh="part_1__2" material="part_1__2_material"/>
        <!-- Link hip_link -->
        <body name="hip_link" pos="0.0105 1.54859e-16 -0.149706" quat="0.5 0.5 0.5 0.5">
          <!-- Joint from part_1 to hip_link -->
          <joint axis="0 0 1" name="pitch" type="hinge"/>
          <inertial pos="0.667869 0.0545192 -0.00976485" mass="1.06123" fullinertia="0.00497483 0.00387499 0.00129427 -1.91128e-05 8.0766e-07 3.18755e-05"/>
          <!-- Part motor_holder -->
          <geom type="mesh" class="visual" pos="0.6858 0.0485 -0.0202675" quat="0.5 -0.5 -0.5 -0.5" mesh="motor_holder" material="motor_holder_material"/>
          <geom type="mesh" class="collision" pos="0.6858 0.0485 -0.0202675" quat="0.5 -0.5 -0.5 -0.5" mesh="motor_holder" material="motor_holder_material"/>
          <!-- Part t_slot_frame -->
          <geom type="mesh" class="visual" pos="0.6958 -0.4472 -0.01" quat="0.5 -0.5 -0.5 -0.5" mesh="t_slot_frame" material="t_slot_frame_material"/>
          <geom type="mesh" class="collision" pos="0.6958 -0.4472 -0.01" quat="0.5 -0.5 -0.5 -0.5" mesh="t_slot_frame" material="t_slot_frame_material"/>
          <!-- Part part_1_3 -->
          <geom type="mesh" class="visual" pos="0.6733 0.066 -0.0747675" quat="0.5 0.5 -0.5 0.5" mesh="part_1__3" material="part_1__3_material"/>
          <geom type="mesh" class="collision" pos="0.6733 0.066 -0.0747675" quat="0.5 0.5 -0.5 0.5" mesh="part_1__3" material="part_1__3_material"/>
          <!-- Part part_1_4 -->
          <geom type="mesh" class="visual" pos="0.6573 0.066 -0.0747675" quat="0.311264 0.634913 -0.634913 0.311264" mesh="part_1__4" material="part_1__4_material"/>
          <geom type="mesh" class="collision" pos="0.6573 0.066 -0.0747675" quat="0.311264 0.634913 -0.634913 0.311264" mesh="part_1__4" material="part_1__4_material"/>
          <!-- Part part_1_5 -->
          <geom type="mesh" class="visual" pos="0.6733 0.066 0.0542675" quat="0.5 0.5 -0.5 0.5" mesh="part_1__3" material="part_1__3_material"/>
          <geom type="mesh" class="collision" pos="0.6733 0.066 0.0542675" quat="0.5 0.5 -0.5 0.5" mesh="part_1__3" material="part_1__3_material"/>
          <!-- Part part_1_6 -->
          <geom type="mesh" class="visual" pos="0.6573 0.066 0.0542675" quat="0.68055 -0.19197 0.19197 0.68055" mesh="part_1__4" material="part_1__4_material"/>
          <geom type="mesh" class="collision" pos="0.6573 0.066 0.0542675" quat="0.68055 -0.19197 0.19197 0.68055" mesh="part_1__4" material="part_1__4_material"/>
          <!-- Frame imu_link -->
          <site group="3" name="imu_link" pos="0.6663 -0.02 -0.0352675" quat="0.707107 0.707107 2.22045e-16 -1.25547e-16"/>
          <!-- Link shaftcouplerleft -->
          <body name="shaftcouplerleft" pos="0.6808 0.066 -0.0747675" quat="0.415627 -0.572061 0.415627 -0.572061">
            <!-- Joint from hip_link to shaftcouplerleft -->
            <joint axis="0 0 1" name="a" type="hinge" range="-2.7052603405912117 0.26179938779914846"/>
            <inertial pos="-0.015993 -0.00519645 0.0297508" mass="0.0357466" fullinertia="8.81377e-06 2.40779e-05 2.12154e-05 -5.54502e-06 3.57263e-06 1.16082e-06"/>
            <!-- Part shaftcouplerleft -->
            <geom type="mesh" class="visual" pos="0 0 0" quat="0.707107 -0.707107 -0 -8.41846e-18" mesh="shaftcouplerleft" material="shaftcouplerleft_material"/>
            <geom type="mesh" class="collision" pos="0 0 0" quat="0.707107 -0.707107 -0 -8.41846e-18" mesh="shaftcouplerleft" material="shaftcouplerleft_material"/>
            <!-- Part 80mm -->
            <geom type="mesh" class="visual" pos="-0.0293289 -0.00952953 0.036" quat="0.698401 0.110616 -0.698401 0.110616" mesh="80mm" material="80mm_material"/>
            <geom type="mesh" class="collision" pos="-0.0293289 -0.00952953 0.036" quat="0.698401 0.110616 -0.698401 0.110616" mesh="80mm" material="80mm_material"/>
            <!-- Frame closing_BR_leg0_1 (1) (1)_2 -->
            <site group="3" name="closing_BR_leg0_1 (1) (1)_2" pos="-0.0588116 -0.0191091 0.028" quat="0.987688 4.19311e-16 0 0.156434"/>
            <!-- Frame closing_BR_leg0_1 (1) (1)_2_z -->
            <site group="3" name="closing_BR_leg0_1 (1) (1)_2_z" pos="-0.0588116 -0.0191091 0.128" quat="0.987688 4.19311e-16 0 0.156434"/>
          </body>
          <!-- Link shaftcouplerright -->
          <body name="shaftcouplerright" pos="0.6808 0.066 0.0542675" quat="0.672499 0.218508 0.672499 0.218508">
            <!-- Joint from hip_link to shaftcouplerright -->
            <joint axis="0 0 1" name="l" type="hinge" range="-1.0471975511965959 2.181661564992914"/>
            <inertial pos="0.00758867 0.0104449 0.0184447" mass="0.0315004" fullinertia="1.10458e-05 7.58983e-06 1.34529e-05 -5.31812e-06 -6.10832e-07 -8.40741e-07"/>
            <!-- Part 68mm -->
            <geom type="mesh" class="visual" pos="0.0145995 0.0200945 0.021" quat="0.32102 -0.630037 -0.32102 -0.630037" mesh="68mm" material="68mm_material"/>
            <geom type="mesh" class="collision" pos="0.0145995 0.0200945 0.021" quat="0.32102 -0.630037 -0.32102 -0.630037" mesh="68mm" material="68mm_material"/>
            <!-- Part shaftcouplerright -->
            <geom type="mesh" class="visual" pos="-5.55112e-17 0 0" quat="0.707107 -0.707107 -0 -2.53304e-17" mesh="shaftcouplerright" material="shaftcouplerright_material"/>
            <geom type="mesh" class="collision" pos="-5.55112e-17 0 0" quat="0.707107 -0.707107 -0 -2.53304e-17" mesh="shaftcouplerright" material="shaftcouplerright_material"/>
            <!-- Link 225mmtop -->
            <body name="225mmtop" pos="-5.55112e-17 -1.11022e-16 0.029" quat="1.0698e-15 -0.824864 0.565331 -3.60717e-16">
              <!-- Joint from shaftcouplerright to 225mmtop -->
              <joint axis="0 0 1" name="BR_leg1_1 (1) (1)" type="hinge" range="-0.1195644629726429 2.062097102020269"/>
              <inertial pos="1.25133e-18 -0.103396 -0.008" mass="0.0562684" fullinertia="0.000237245 2.00635e-06 0.000237309 -5.97315e-21 3.3136e-34 -3.4686e-34"/>
              <!-- Part 225mmtop -->
              <geom type="mesh" class="visual" pos="0 -0.1035 -0.008" quat="0.5 0.5 0.5 -0.5" mesh="225mmtop" material="225mmtop_material"/>
              <geom type="mesh" class="collision" pos="0 -0.1035 -0.008" quat="0.5 0.5 0.5 -0.5" mesh="225mmtop" material="225mmtop_material"/>
              <!-- Frame closing_BR_leg3_1 (1) (1)_2 -->
              <site group="3" name="closing_BR_leg3_1 (1) (1)_2" pos="2.77556e-17 -0.207 0" quat="4.94109e-31 -0.707107 -0.707107 3.29722e-31"/>
              <!-- Frame closing_BR_leg3_1 (1) (1)_2_z -->
              <site group="3" name="closing_BR_leg3_1 (1) (1)_2_z" pos="2.77556e-17 -0.207 -0.1" quat="4.94109e-31 -0.707107 -0.707107 3.29722e-31"/>
              <!-- Link 105mm -->
              <body name="105mm" pos="2.77556e-17 -0.166278 -1.11022e-16" quat="0 1 0 0">
                <!-- Joint from 225mmtop to 105mm -->
                <joint axis="0 0 1" name="BR_leg_cyl_0_1 (1) (1)" type="hinge"/>
                <inertial pos="0.0374284 -0.0221668 -0.009" mass="0.0262025" fullinertia="7.06118e-06 1.83254e-05 2.44536e-05 1.02753e-05 -5.92086e-20 -1.17201e-19"/>
                <!-- Part 105mm -->
                <geom type="mesh" class="visual" pos="0.0374284 -0.0221668 -0.009" quat="0.186801 0.681986 -0.186801 0.681986" mesh="105mm" material="105mm_material"/>
                <geom type="mesh" class="collision" pos="0.0374284 -0.0221668 -0.009" quat="0.186801 0.681986 -0.186801 0.681986" mesh="105mm" material="105mm_material"/>
                <!-- Frame closing_BR_leg0_1 (1) (1)_1 -->
                <site group="3" name="closing_BR_leg0_1 (1) (1)_1" pos="0.0748567 -0.0443336 -0.001" quat="0.495186 -8.51481e-16 -3.05311e-15 -0.868787"/>
                <!-- Frame closing_BR_leg0_1 (1) (1)_1_z -->
                <site group="3" name="closing_BR_leg0_1 (1) (1)_1_z" pos="0.0748567 -0.0443336 0.099" quat="0.495186 -8.51481e-16 -3.05311e-15 -0.868787"/>
              </body>
            </body>
            <!-- Link 225mmbottom -->
            <body name="225mmbottom" pos="0.0292942 0.0403199 0.029" quat="4.00055e-17 0.82527 -0.564738 -9.24542e-16">
              <!-- Joint from shaftcouplerright to 225mmbottom -->
              <joint axis="0 0 1" name="BR_leg2_1 (1) (1)" type="hinge" range="-0.13558074228853306 2.220613747903812"/>
              <inertial pos="5.88206e-17 -0.1035 -0.008" mass="0.0563618" fullinertia="0.000237565 1.94076e-06 0.000237608 1.35657e-20 9.24595e-35 -1.22493e-35"/>
              <!-- Part 225mmbottom -->
              <geom type="mesh" class="visual" pos="5.55112e-17 -0.1035 -0.008" quat="0.5 -0.5 -0.5 -0.5" mesh="225mmbottom" material="225mmbottom_material"/>
              <geom type="mesh" class="collision" pos="5.55112e-17 -0.1035 -0.008" quat="0.5 -0.5 -0.5 -0.5" mesh="225mmbottom" material="225mmbottom_material"/>
              <!-- Link 160mm -->
              <body name="160mm" pos="5.55112e-17 -0.207 -1.11022e-16" quat="0 1 0 0">
                <!-- Joint from 225mmbottom to 160mm -->
                <joint axis="0 0 1" name="BR_leg_cyl_1_1 (1) (1)" type="hinge" range="-0.14058096346681337 2.128347064125815"/>
                <inertial pos="-0.0115677 0.0177756 -0.008" mass="0.0400222" fullinertia="6.08306e-05 2.65789e-05 8.60343e-05 3.86638e-05 -1.73339e-19 -9.20495e-20"/>
                <!-- Part 160mm -->
                <geom type="mesh" class="visual" pos="-0.0114542 0.0176012 -0.008" quat="0.337106 0.621579 -0.337106 0.621579" mesh="160mm" material="160mm_material"/>
                <geom type="mesh" class="collision" pos="-0.0114542 0.0176012 -0.008" quat="0.337106 0.621579 -0.337106 0.621579" mesh="160mm" material="160mm_material"/>
                <!-- Frame closing_BR_leg3_1 (1) (1)_1 -->
                <site group="3" name="closing_BR_leg3_1 (1) (1)_1" pos="0.027272 -0.0419075 -6.66134e-16" quat="0.284473 -1.4208e-15 2.66454e-15 -0.958684"/>
                <!-- Frame closing_BR_leg3_1 (1) (1)_1_z -->
                <site group="3" name="closing_BR_leg3_1 (1) (1)_1_z" pos="0.027272 -0.0419075 0.1" quat="0.284473 -1.4208e-15 2.66454e-15 -0.958684"/>
              </body>
            </body>
          </body>
        </body>
      </body>
    </body>
  </worldbody>
  <asset>
    <mesh file="68mm.stl"/>
    <mesh file="80mm.stl"/>
    <mesh file="225mmtop.stl"/>
    <mesh file="105mm.stl"/>
    <mesh file="part_1__4.stl"/>
    <mesh file="motor_holder.stl"/>
    <mesh file="part_1__2.stl"/>
    <mesh file="shaftcouplerleft.stl"/>
    <mesh file="part_1__3.stl"/>
    <mesh file="225mmbottom.stl"/>
    <mesh file="t_slot_frame.stl"/>
    <mesh file="160mm.stl"/>
    <mesh file="part_1.stl"/>
    <mesh file="shaftcouplerright.stl"/>
    <material name="part_1_material" rgba="0.47451 0.352941 0 1"/>
    <material name="part_1__2_material" rgba="0.615686 0.811765 0.929412 1"/>
    <material name="motor_holder_material" rgba="0.917647 0.917647 0.917647 1"/>
    <material name="t_slot_frame_material" rgba="0.752941 0.752941 0.752941 1"/>
    <material name="part_1__3_material" rgba="0.498039 0.498039 0.498039 1"/>
    <material name="part_1__4_material" rgba="0.647059 0.647059 0.647059 1"/>
    <material name="shaftcouplerleft_material" rgba="0.917647 0.917647 0.917647 1"/>
    <material name="80mm_material" rgba="0.882353 0.572549 0.478431 1"/>
    <material name="68mm_material" rgba="0.882353 0.572549 0.478431 1"/>
    <material name="shaftcouplerright_material" rgba="0.917647 0.917647 0.917647 1"/>
    <material name="225mmtop_material" rgba="0.917647 0.917647 0.917647 1"/>
    <material name="105mm_material" rgba="0.917647 0.917647 0.917647 1"/>
    <material name="225mmbottom_material" rgba="0.917647 0.917647 0.917647 1"/>
    <material name="160mm_material" rgba="0.917647 0.917647 0.917647 1"/>
  </asset>
  <actuator>
    <continuous class="robot" name="yaw" joint="yaw"/>
    <position class="robot" name="pitch" joint="pitch"/>
    <position class="robot" name="a" joint="a" inheritrange="1"/>
    <position class="robot" name="l" joint="l" inheritrange="1"/>
    <position class="robot" name="BR_leg1_1 (1) (1)" joint="BR_leg1_1 (1) (1)" inheritrange="1"/>
    <position class="robot" name="BR_leg_cyl_0_1 (1) (1)" joint="BR_leg_cyl_0_1 (1) (1)"/>
    <position class="robot" name="BR_leg2_1 (1) (1)" joint="BR_leg2_1 (1) (1)" inheritrange="1"/>
    <position class="robot" name="BR_leg_cyl_1_1 (1) (1)" joint="BR_leg_cyl_1_1 (1) (1)" inheritrange="1"/>
  </actuator>
  <equality>
    <connect site1="closing_BR_leg0_1 (1) (1)_1" site2="closing_BR_leg0_1 (1) (1)_2"/>
    <connect site1="closing_BR_leg0_1 (1) (1)_1_z" site2="closing_BR_leg0_1 (1) (1)_2_z"/>
    <connect site1="closing_BR_leg3_1 (1) (1)_1" site2="closing_BR_leg3_1 (1) (1)_2"/>
    <connect site1="closing_BR_leg3_1 (1) (1)_1_z" site2="closing_BR_leg3_1 (1) (1)_2_z"/>
  </equality>
</mujoco>
